#VRML_SIM R2023a utf8

EXTERNPROTO "https://raw.githubusercontent.com/cyberbotics/webots/R2023a/projects/objects/backgrounds/protos/TexturedBackground.proto"
EXTERNPROTO "https://raw.githubusercontent.com/cyberbotics/webots/R2023a/projects/objects/backgrounds/protos/TexturedBackgroundLight.proto"
EXTERNPROTO "https://raw.githubusercontent.com/cyberbotics/webots/R2023a/projects/objects/road/protos/StraightRoadSegment.proto"
EXTERNPROTO "https://raw.githubusercontent.com/cyberbotics/webots/R2023a/projects/objects/floors/protos/Floor.proto"
EXTERNPROTO "https://raw.githubusercontent.com/cyberbotics/webots/R2023a/projects/appearances/protos/Grass.proto"
EXTERNPROTO "https://raw.githubusercontent.com/cyberbotics/webots/R2023a/projects/objects/tables/protos/Table.proto"
EXTERNPROTO "https://raw.githubusercontent.com/cyberbotics/webots/R2023a/projects/objects/advertising_board/protos/AdvertisingBoard.proto"
EXTERNPROTO "https://raw.githubusercontent.com/cyberbotics/webots/R2023a/projects/objects/obstacles/protos/OilBarrel.proto"
EXTERNPROTO "https://raw.githubusercontent.com/cyberbotics/webots/R2023a/projects/objects/animals/protos/Dog.proto"
EXTERNPROTO "https://raw.githubusercontent.com/cyberbotics/webots/R2023a/projects/objects/animals/protos/Rabbit.proto"
EXTERNPROTO "https://raw.githubusercontent.com/cyberbotics/webots/R2023a/projects/objects/garden/protos/Gnome.proto"
EXTERNPROTO "https://raw.githubusercontent.com/cyberbotics/webots/R2023a/projects/objects/factory/forklift/protos/Forklift.proto"
EXTERNPROTO "../protos/Iris.proto"
EXTERNPROTO "../protos/ArucoMarker.proto"

WorldInfo {
  title "Iris Ardupilot"
  basicTimeStep 2
  FPS 20
}
Viewpoint {
  orientation -0.08983892055611123 -0.02969228966773966 0.995513604270479 3.777325299404198
  position 1.217037677764462 2.2404954274190825 1.022599441000403
  follow "Iris"
  followSmoothness 0.01
}
TexturedBackground {
}
TexturedBackgroundLight {
}
Floor {
  size 300 100
  appearance Grass {
  }
}
StraightRoadSegment {
  translation -15 0.3 0.02
  rotation 0 0 1 0.105
  width 16.5
  rightBorder FALSE
  leftBorder FALSE
  length 140
}
Rabbit {
  translation 4.68362 1.88178 0.88
  rotation 0 0 1 2.61799
  name "nibbles"
}
Gnome {
  translation 5.87588 0.590355 3.6788e-21
  rotation 0 0 1 2.61799
}
Forklift {
  translation 9.19827 2.56008 0.81
  rotation 0 0 1 -2.3561953071795863
  enablePhysics FALSE
}
Dog {
  translation 5.97592 3.52 1.77636e-15
  rotation 0 0 1 -2.6179953071795863
  name "bentley"
}
OilBarrel {
  translation 4.54625 1.79835 0.44
}
AdvertisingBoard {
  translation 13.1012 17.8267 0
  rotation 0 0 1 -1.469
  frontTexture [
    "../../../../../Tools/autotest/web-firmware/images/logo.png"
  ]
  backTexture [
    "../../../../../Tools/autotest/web-firmware/images/logo.png"
  ]
  displayWidth 16.28
  displayHeight 6
  poleNumber 2
  poleType "H-shape"
  poleHeight 10
}
Table {
  translation 0 0.92 0
}
Iris {
  hidden linearVelocity_0 1.1826888315211503e-10 8.6214208529204e-10 5.4396805977916306e-11
  hidden angularVelocity_0 1.1243847047704685e-09 -2.57615014023143e-10 2.0521650292989826e-09
  hidden linearVelocity_1 7.470190741149251e-10 2.085954651542206e-09 7.854523032500353e-11
  hidden angularVelocity_1 -5.875464635861374e-09 -2.710607066114359e-10 1.0600514694516434e-07
  hidden linearVelocity_2 4.491495392071986e-10 2.9766099005794037e-09 4.6071103719924205e-11
  hidden angularVelocity_2 -5.854330028661887e-09 -2.474656654426283e-10 1.0596826869757202e-07
  hidden linearVelocity_3 -1.4054447800477593e-10 3.891055130391601e-09 -1.9339121317726857e-12
  hidden angularVelocity_3 -2.828369930072194e-07 -3.059056513828245e-10 8.716531288034931e-08
  translation 0.0654297681014562 1.4503750028273734 0.8107462179779619
  rotation 0.00021243147858502283 -0.9999957254446683 0.0029161559043809735 0.06763073852364089
  controller "ardupilot_vehicle_controller"
  controllerArgs [
    "--motors"
    "m1_motor, m2_motor, m3_motor, m4_motor"
    "--camera"
    "camera"
    "--camera-port"
    "5599"
  ]
  extensionSlot [
    Transform {
      translation 0 0 -0.03
      children [
        DEF CAMERA_YAW HingeJoint {
          jointParameters HingeJointParameters {
            position -2.0254374177852696e-08
            axis 0 0 1
            anchor 0.0412774 -0.00469654 -0.00405862
          }
          device [
            RotationalMotor {
              name "camera yaw"
              minPosition -1.7
              maxPosition 1.7
            }
            PositionSensor {
              name "camera yaw sensor"
            }
          ]
          endPoint Solid {
            translation 0.0412774 -0.00469654 -0.00405862
            children [
              Shape {
                appearance DEF METAL_APPEARANCE PBRAppearance {
                  roughness 0.5
                }
                geometry Mesh {
                  url [
                    "https://raw.githubusercontent.com/cyberbotics/webots/R2023a/projects/robots/dji/mavic/protos/Mavic2Pro/meshes/camera_yaw.obj"
                  ]
                }
              }
              DEF CAMERA_PITCH HingeJoint {
                jointParameters HingeJointParameters {
                  position 1.6772385173332406e-07
                  axis 0 1 0
                  anchor 0.000625212 -0.00530346 -0.0207448
                }
                device [
                  RotationalMotor {
                    name "camera pitch"
                    minPosition -0.5
                    maxPosition 1.7
                  }
                  PositionSensor {
                    name "camera pitch sensor"
                  }
                ]
                endPoint Solid {
                  translation 0.000625212 -0.00530346 -0.0207448
                  rotation 0 0.9999999999999999 0 1.6858739404357617e-07
                  children [
                    Shape {
                      appearance USE METAL_APPEARANCE
                      geometry Mesh {
                        url [
                          "https://raw.githubusercontent.com/cyberbotics/webots/R2023a/projects/robots/dji/mavic/protos/Mavic2Pro/meshes/camera_pitch.obj"
                        ]
                      }
                    }
                    DEF CAMERA_ROLL HingeJoint {
                      jointParameters HingeJointParameters {
                        position -2.7597341501781813e-08
                        anchor 0.00754686 0.0160388 -0.00586401
                      }
                      device [
                        RotationalMotor {
                          name "camera roll"
                          minPosition -0.5
                          maxPosition 0.5
                        }
                        PositionSensor {
                          name "camera roll sensor"
                        }
                      ]
                      endPoint Solid {
                        translation 0.00754686 0.0160388 -0.00586401
                        rotation -1 0 0 2.9802322387695313e-08
                        children [
                          Shape {
                            appearance USE METAL_APPEARANCE
                            geometry Mesh {
                              url [
                                "https://raw.githubusercontent.com/cyberbotics/webots/R2023a/projects/robots/dji/mavic/protos/Mavic2Pro/meshes/camera_chassis.obj"
                              ]
                            }
                          }
                          Shape {
                            appearance DEF GLASS PBRAppearance {
                              baseColor 0.523146 0.8 0.627785
                              transparency 0.9
                              roughness 0.5
                              metalness 0
                            }
                            geometry Mesh {
                              url [
                                "https://raw.githubusercontent.com/cyberbotics/webots/R2023a/projects/robots/dji/mavic/protos/Mavic2Pro/meshes/camera_lens.obj"
                              ]
                            }
                          }
                          DEF CAMERA_SLOT Transform {
                            children [
                              Camera {
                                width 400
                                height 240
                              }
                            ]
                          }
                        ]
                        name "camera roll"
                        boundingObject Transform {
                          translation -0.00915058 -1.86265e-08 -0.000983764
                          children [
                            Box {
                              size 0.0236511 0.0205141 0.0225186
                            }
                          ]
                        }
                        physics Physics {
                          density -1
                          mass 0.0333
                        }
                      }
                    }
                  ]
                  name "camera pitch"
                  boundingObject Transform {
                    translation -0.00248347 0.00776876 0.00183829
                    children [
                      Box {
                        size 0.0239878 0.0349393 0.0314891
                      }
                    ]
                  }
                  physics Physics {
                    density -1
                    mass 0.0333
                  }
                }
              }
            ]
            name "camera yaw"
            boundingObject Transform {
              translation -1.86265e-09 -0.00304481 -0.0140589
              children [
                Box {
                  size 0.0208626 0.0260333 0.0307844
                }
              ]
            }
            physics Physics {
              density -1
              mass 0.0333
            }
          }
        }
      ]
    }
  ]
}
ArucoMarker {
  translation 4.23295 1.80428 0.72
  rotation 0 1 0 -1.5707953071795862
  name "aruco 0"
  size 0.2
}
ArucoMarker {
  translation 4.39446 1.53182 0.44
  rotation 0.44721372362178063 -0.7745965212991105 0.44721372362178063 1.82348
  name "aruco 1"
  size 0.2
  markerId "1"
}
